2025-08-09 00:02:01 ERROR Internal Server Error: /en/i18n/setlang/ C:\Users\kores\PycharmProjects\NewSite\NewsSite\venv\Lib\site-packages\django\utils\log.py
None
Traceback (most recent call last):
  File "C:\Users\kores\PycharmProjects\NewSite\NewsSite\venv\Lib\site-packages\django\core\handlers\exception.py", line 55, in inner
    response = get_response(request)
  File "C:\Users\kores\PycharmProjects\NewSite\NewsSite\venv\Lib\site-packages\django\utils\deprecation.py", line 119, in __call__
    response = self.process_request(request)
  File "C:\Users\kores\PycharmProjects\NewSite\NewsSite\venv\Lib\site-packages\django\middleware\locale.py", line 35, in process_request
    translation.activate(language)
    ~~~~~~~~~~~~~~~~~~~~^^^^^^^^^^
  File "C:\Users\kores\PycharmProjects\NewSite\NewsSite\venv\Lib\site-packages\django\utils\translation\__init__.py", line 182, in activate
    return _trans.activate(language)
           ~~~~~~~~~~~~~~~^^^^^^^^^^
  File "C:\Users\kores\PycharmProjects\NewSite\NewsSite\venv\Lib\site-packages\django\utils\translation\trans_real.py", line 302, in activate
    _active.value = translation(language)
                    ~~~~~~~~~~~^^^^^^^^^^
  File "C:\Users\kores\PycharmProjects\NewSite\NewsSite\venv\Lib\site-packages\django\utils\translation\trans_real.py", line 291, in translation
    _translations[language] = DjangoTranslation(language)
                              ~~~~~~~~~~~~~~~~~^^^^^^^^^^
  File "C:\Users\kores\PycharmProjects\NewSite\NewsSite\venv\Lib\site-packages\django\utils\translation\trans_real.py", line 171, in __init__
    self._add_local_translations()
    ~~~~~~~~~~~~~~~~~~~~~~~~~~~~^^
  File "C:\Users\kores\PycharmProjects\NewSite\NewsSite\venv\Lib\site-packages\django\utils\translation\trans_real.py", line 231, in _add_local_translations
    translation = self._new_gnu_trans(localedir)
  File "C:\Users\kores\PycharmProjects\NewSite\NewsSite\venv\Lib\site-packages\django\utils\translation\trans_real.py", line 198, in _new_gnu_trans
    return gettext_module.translation(
           ~~~~~~~~~~~~~~~~~~~~~~~~~~^
        domain=self.domain,
        ^^^^^^^^^^^^^^^^^^^
    ...<2 lines>...
        fallback=use_null_fallback,
        ^^^^^^^^^^^^^^^^^^^^^^^^^^^
    )
    ^
  File "C:\Users\kores\AppData\Local\Programs\Python\Python313\Lib\gettext.py", line 547, in translation
    t = _translations.setdefault(key, class_(fp))
                                      ~~~~~~^^^^
  File "C:\Users\kores\AppData\Local\Programs\Python\Python313\Lib\gettext.py", line 279, in __init__
    self._parse(fp)
    ~~~~~~~~~~~^^^^
  File "C:\Users\kores\AppData\Local\Programs\Python\Python313\Lib\gettext.py", line 370, in _parse
    raise OSError(0, 'Bad magic number', filename)
OSError: [Errno 0] Bad magic number: 'C:\\Users\\kores\\PycharmProjects\\NewSite\\NewsSite\\locale\\en\\LC_MESSAGES\\django.mo'
2025-08-09 00:02:01 ERROR "POST /en/i18n/setlang/ HTTP/1.1" 500 111277 C:\Users\kores\PycharmProjects\NewSite\NewsSite\venv\Lib\site-packages\django\core\servers\basehttp.py
None
2025-08-11 19:02:37 ERROR Internal Server Error: /news/profile/ C:\Users\kores\PycharmProjects\NewSite\NewsSite\venv\Lib\site-packages\django\utils\log.py
None
Traceback (most recent call last):
  File "C:\Users\kores\PycharmProjects\NewSite\NewsSite\venv\Lib\site-packages\django\template\base.py", line 510, in parse
    compile_func = self.tags[command]
                   ~~~~~~~~~^^^^^^^^^
KeyError: 'trans'

During handling of the above exception, another exception occurred:

Traceback (most recent call last):
  File "C:\Users\kores\PycharmProjects\NewSite\NewsSite\venv\Lib\site-packages\django\core\handlers\exception.py", line 55, in inner
    response = get_response(request)
  File "C:\Users\kores\PycharmProjects\NewSite\NewsSite\venv\Lib\site-packages\django\core\handlers\base.py", line 197, in _get_response
    response = wrapped_callback(request, *callback_args, **callback_kwargs)
  File "C:\Users\kores\PycharmProjects\NewSite\NewsSite\venv\Lib\site-packages\django\contrib\auth\decorators.py", line 59, in _view_wrapper
    return view_func(request, *args, **kwargs)
  File "C:\Users\kores\PycharmProjects\NewSite\NewsSite\news\views.py", line 49, in profile_view
    return render(request, 'profile.html')
  File "C:\Users\kores\PycharmProjects\NewSite\NewsSite\venv\Lib\site-packages\django\shortcuts.py", line 25, in render
    content = loader.render_to_string(template_name, context, request, using=using)
  File "C:\Users\kores\PycharmProjects\NewSite\NewsSite\venv\Lib\site-packages\django\template\loader.py", line 61, in render_to_string
    template = get_template(template_name, using=using)
  File "C:\Users\kores\PycharmProjects\NewSite\NewsSite\venv\Lib\site-packages\django\template\loader.py", line 15, in get_template
    return engine.get_template(template_name)
           ~~~~~~~~~~~~~~~~~~~^^^^^^^^^^^^^^^
  File "C:\Users\kores\PycharmProjects\NewSite\NewsSite\venv\Lib\site-packages\django\template\backends\django.py", line 79, in get_template
    return Template(self.engine.get_template(template_name), self)
                    ~~~~~~~~~~~~~~~~~~~~~~~~^^^^^^^^^^^^^^^
  File "C:\Users\kores\PycharmProjects\NewSite\NewsSite\venv\Lib\site-packages\django\template\engine.py", line 177, in get_template
    template, origin = self.find_template(template_name)
                       ~~~~~~~~~~~~~~~~~~^^^^^^^^^^^^^^^
  File "C:\Users\kores\PycharmProjects\NewSite\NewsSite\venv\Lib\site-packages\django\template\engine.py", line 159, in find_template
    template = loader.get_template(name, skip=skip)
  File "C:\Users\kores\PycharmProjects\NewSite\NewsSite\venv\Lib\site-packages\django\template\loaders\cached.py", line 57, in get_template
    template = super().get_template(template_name, skip)
  File "C:\Users\kores\PycharmProjects\NewSite\NewsSite\venv\Lib\site-packages\django\template\loaders\base.py", line 28, in get_template
    return Template(
        contents,
    ...<2 lines>...
        self.engine,
    )
  File "C:\Users\kores\PycharmProjects\NewSite\NewsSite\venv\Lib\site-packages\django\template\base.py", line 154, in __init__
    self.nodelist = self.compile_nodelist()
                    ~~~~~~~~~~~~~~~~~~~~~^^
  File "C:\Users\kores\PycharmProjects\NewSite\NewsSite\venv\Lib\site-packages\django\template\base.py", line 196, in compile_nodelist
    nodelist = parser.parse()
  File "C:\Users\kores\PycharmProjects\NewSite\NewsSite\venv\Lib\site-packages\django\template\base.py", line 518, in parse
    raise self.error(token, e)
  File "C:\Users\kores\PycharmProjects\NewSite\NewsSite\venv\Lib\site-packages\django\template\base.py", line 516, in parse
    compiled_result = compile_func(self, token)
  File "C:\Users\kores\PycharmProjects\NewSite\NewsSite\venv\Lib\site-packages\django\template\loader_tags.py", line 299, in do_extends
    nodelist = parser.parse()
  File "C:\Users\kores\PycharmProjects\NewSite\NewsSite\venv\Lib\site-packages\django\template\base.py", line 518, in parse
    raise self.error(token, e)
  File "C:\Users\kores\PycharmProjects\NewSite\NewsSite\venv\Lib\site-packages\django\template\base.py", line 516, in parse
    compiled_result = compile_func(self, token)
  File "C:\Users\kores\PycharmProjects\NewSite\NewsSite\venv\Lib\site-packages\django\template\loader_tags.py", line 234, in do_block
    nodelist = parser.parse(("endblock",))
  File "C:\Users\kores\PycharmProjects\NewSite\NewsSite\venv\Lib\site-packages\django\template\base.py", line 512, in parse
    self.invalid_block_tag(token, command, parse_until)
    ~~~~~~~~~~~~~~~~~~~~~~^^^^^^^^^^^^^^^^^^^^^^^^^^^^^
  File "C:\Users\kores\PycharmProjects\NewSite\NewsSite\venv\Lib\site-packages\django\template\base.py", line 567, in invalid_block_tag
    raise self.error(
    ...<8 lines>...
    )
django.template.exceptions.TemplateSyntaxError: Invalid block tag on line 28: 'trans', expected 'endblock'. Did you forget to register or load this tag?
2025-08-11 19:02:37 ERROR "GET /news/profile/ HTTP/1.1" 500 180175 C:\Users\kores\PycharmProjects\NewSite\NewsSite\venv\Lib\site-packages\django\core\servers\basehttp.py
None
2025-08-11 20:31:20 ERROR Internal Server Error: /profile/ C:\Users\kores\PycharmProjects\NewSite\NewsSite\venv\Lib\site-packages\django\utils\log.py
None
Traceback (most recent call last):
  File "C:\Users\kores\PycharmProjects\NewSite\NewsSite\venv\Lib\site-packages\django\core\handlers\exception.py", line 55, in inner
    response = get_response(request)
  File "C:\Users\kores\PycharmProjects\NewSite\NewsSite\venv\Lib\site-packages\django\core\handlers\base.py", line 197, in _get_response
    response = wrapped_callback(request, *callback_args, **callback_kwargs)
  File "C:\Users\kores\PycharmProjects\NewSite\NewsSite\venv\Lib\site-packages\django\contrib\auth\decorators.py", line 59, in _view_wrapper
    return view_func(request, *args, **kwargs)
  File "C:\Users\kores\PycharmProjects\NewSite\NewsSite\news\views.py", line 78, in profile_view
    return render(request, 'profile.html')
  File "C:\Users\kores\PycharmProjects\NewSite\NewsSite\venv\Lib\site-packages\django\shortcuts.py", line 25, in render
    content = loader.render_to_string(template_name, context, request, using=using)
  File "C:\Users\kores\PycharmProjects\NewSite\NewsSite\venv\Lib\site-packages\django\template\loader.py", line 62, in render_to_string
    return template.render(context, request)
           ~~~~~~~~~~~~~~~^^^^^^^^^^^^^^^^^^
  File "C:\Users\kores\PycharmProjects\NewSite\NewsSite\venv\Lib\site-packages\django\template\backends\django.py", line 107, in render
    return self.template.render(context)
           ~~~~~~~~~~~~~~~~~~~~^^^^^^^^^
  File "C:\Users\kores\PycharmProjects\NewSite\NewsSite\venv\Lib\site-packages\django\template\base.py", line 171, in render
    return self._render(context)
           ~~~~~~~~~~~~^^^^^^^^^
  File "C:\Users\kores\PycharmProjects\NewSite\NewsSite\venv\Lib\site-packages\django\template\base.py", line 163, in _render
    return self.nodelist.render(context)
           ~~~~~~~~~~~~~~~~~~~~^^^^^^^^^
  File "C:\Users\kores\PycharmProjects\NewSite\NewsSite\venv\Lib\site-packages\django\template\base.py", line 1016, in render
    return SafeString("".join([node.render_annotated(context) for node in self]))
                               ~~~~~~~~~~~~~~~~~~~~~^^^^^^^^^
  File "C:\Users\kores\PycharmProjects\NewSite\NewsSite\venv\Lib\site-packages\django\template\base.py", line 977, in render_annotated
    return self.render(context)
           ~~~~~~~~~~~^^^^^^^^^
  File "C:\Users\kores\PycharmProjects\NewSite\NewsSite\venv\Lib\site-packages\django\template\loader_tags.py", line 159, in render
    return compiled_parent._render(context)
           ~~~~~~~~~~~~~~~~~~~~~~~^^^^^^^^^
  File "C:\Users\kores\PycharmProjects\NewSite\NewsSite\venv\Lib\site-packages\django\template\base.py", line 163, in _render
    return self.nodelist.render(context)
           ~~~~~~~~~~~~~~~~~~~~^^^^^^^^^
  File "C:\Users\kores\PycharmProjects\NewSite\NewsSite\venv\Lib\site-packages\django\template\base.py", line 1016, in render
    return SafeString("".join([node.render_annotated(context) for node in self]))
                               ~~~~~~~~~~~~~~~~~~~~~^^^^^^^^^
  File "C:\Users\kores\PycharmProjects\NewSite\NewsSite\venv\Lib\site-packages\django\template\base.py", line 977, in render_annotated
    return self.render(context)
           ~~~~~~~~~~~^^^^^^^^^
  File "C:\Users\kores\PycharmProjects\NewSite\NewsSite\venv\Lib\site-packages\django\templatetags\cache.py", line 53, in render
    value = self.nodelist.render(context)
  File "C:\Users\kores\PycharmProjects\NewSite\NewsSite\venv\Lib\site-packages\django\template\base.py", line 1016, in render
    return SafeString("".join([node.render_annotated(context) for node in self]))
                               ~~~~~~~~~~~~~~~~~~~~~^^^^^^^^^
  File "C:\Users\kores\PycharmProjects\NewSite\NewsSite\venv\Lib\site-packages\django\template\base.py", line 977, in render_annotated
    return self.render(context)
           ~~~~~~~~~~~^^^^^^^^^
  File "C:\Users\kores\PycharmProjects\NewSite\NewsSite\venv\Lib\site-packages\django\template\defaulttags.py", line 327, in render
    return nodelist.render(context)
           ~~~~~~~~~~~~~~~^^^^^^^^^
  File "C:\Users\kores\PycharmProjects\NewSite\NewsSite\venv\Lib\site-packages\django\template\base.py", line 1016, in render
    return SafeString("".join([node.render_annotated(context) for node in self]))
                               ~~~~~~~~~~~~~~~~~~~~~^^^^^^^^^
  File "C:\Users\kores\PycharmProjects\NewSite\NewsSite\venv\Lib\site-packages\django\template\base.py", line 977, in render_annotated
    return self.render(context)
           ~~~~~~~~~~~^^^^^^^^^
  File "C:\Users\kores\PycharmProjects\NewSite\NewsSite\venv\Lib\site-packages\django\template\defaulttags.py", line 480, in render
    url = reverse(view_name, args=args, kwargs=kwargs, current_app=current_app)
  File "C:\Users\kores\PycharmProjects\NewSite\NewsSite\venv\Lib\site-packages\django\urls\base.py", line 98, in reverse
    resolved_url = resolver._reverse_with_prefix(view, prefix, *args, **kwargs)
  File "C:\Users\kores\PycharmProjects\NewSite\NewsSite\venv\Lib\site-packages\django\urls\resolvers.py", line 831, in _reverse_with_prefix
    raise NoReverseMatch(msg)
django.urls.exceptions.NoReverseMatch: Reverse for 'account_logout' not found. 'account_logout' is not a valid view function or pattern name.
2025-08-11 20:31:20 ERROR "GET /profile/ HTTP/1.1" 500 175994 C:\Users\kores\PycharmProjects\NewSite\NewsSite\venv\Lib\site-packages\django\core\servers\basehttp.py
None
2025-08-11 20:31:24 ERROR Internal Server Error: /news/profile/ C:\Users\kores\PycharmProjects\NewSite\NewsSite\venv\Lib\site-packages\django\utils\log.py
None
Traceback (most recent call last):
  File "C:\Users\kores\PycharmProjects\NewSite\NewsSite\venv\Lib\site-packages\django\core\handlers\exception.py", line 55, in inner
    response = get_response(request)
  File "C:\Users\kores\PycharmProjects\NewSite\NewsSite\venv\Lib\site-packages\django\core\handlers\base.py", line 197, in _get_response
    response = wrapped_callback(request, *callback_args, **callback_kwargs)
  File "C:\Users\kores\PycharmProjects\NewSite\NewsSite\venv\Lib\site-packages\django\contrib\auth\decorators.py", line 59, in _view_wrapper
    return view_func(request, *args, **kwargs)
  File "C:\Users\kores\PycharmProjects\NewSite\NewsSite\news\views.py", line 78, in profile_view
    return render(request, 'profile.html')
  File "C:\Users\kores\PycharmProjects\NewSite\NewsSite\venv\Lib\site-packages\django\shortcuts.py", line 25, in render
    content = loader.render_to_string(template_name, context, request, using=using)
  File "C:\Users\kores\PycharmProjects\NewSite\NewsSite\venv\Lib\site-packages\django\template\loader.py", line 62, in render_to_string
    return template.render(context, request)
           ~~~~~~~~~~~~~~~^^^^^^^^^^^^^^^^^^
  File "C:\Users\kores\PycharmProjects\NewSite\NewsSite\venv\Lib\site-packages\django\template\backends\django.py", line 107, in render
    return self.template.render(context)
           ~~~~~~~~~~~~~~~~~~~~^^^^^^^^^
  File "C:\Users\kores\PycharmProjects\NewSite\NewsSite\venv\Lib\site-packages\django\template\base.py", line 171, in render
    return self._render(context)
           ~~~~~~~~~~~~^^^^^^^^^
  File "C:\Users\kores\PycharmProjects\NewSite\NewsSite\venv\Lib\site-packages\django\template\base.py", line 163, in _render
    return self.nodelist.render(context)
           ~~~~~~~~~~~~~~~~~~~~^^^^^^^^^
  File "C:\Users\kores\PycharmProjects\NewSite\NewsSite\venv\Lib\site-packages\django\template\base.py", line 1016, in render
    return SafeString("".join([node.render_annotated(context) for node in self]))
                               ~~~~~~~~~~~~~~~~~~~~~^^^^^^^^^
  File "C:\Users\kores\PycharmProjects\NewSite\NewsSite\venv\Lib\site-packages\django\template\base.py", line 977, in render_annotated
    return self.render(context)
           ~~~~~~~~~~~^^^^^^^^^
  File "C:\Users\kores\PycharmProjects\NewSite\NewsSite\venv\Lib\site-packages\django\template\loader_tags.py", line 159, in render
    return compiled_parent._render(context)
           ~~~~~~~~~~~~~~~~~~~~~~~^^^^^^^^^
  File "C:\Users\kores\PycharmProjects\NewSite\NewsSite\venv\Lib\site-packages\django\template\base.py", line 163, in _render
    return self.nodelist.render(context)
           ~~~~~~~~~~~~~~~~~~~~^^^^^^^^^
  File "C:\Users\kores\PycharmProjects\NewSite\NewsSite\venv\Lib\site-packages\django\template\base.py", line 1016, in render
    return SafeString("".join([node.render_annotated(context) for node in self]))
                               ~~~~~~~~~~~~~~~~~~~~~^^^^^^^^^
  File "C:\Users\kores\PycharmProjects\NewSite\NewsSite\venv\Lib\site-packages\django\template\base.py", line 977, in render_annotated
    return self.render(context)
           ~~~~~~~~~~~^^^^^^^^^
  File "C:\Users\kores\PycharmProjects\NewSite\NewsSite\venv\Lib\site-packages\django\templatetags\cache.py", line 53, in render
    value = self.nodelist.render(context)
  File "C:\Users\kores\PycharmProjects\NewSite\NewsSite\venv\Lib\site-packages\django\template\base.py", line 1016, in render
    return SafeString("".join([node.render_annotated(context) for node in self]))
                               ~~~~~~~~~~~~~~~~~~~~~^^^^^^^^^
  File "C:\Users\kores\PycharmProjects\NewSite\NewsSite\venv\Lib\site-packages\django\template\base.py", line 977, in render_annotated
    return self.render(context)
           ~~~~~~~~~~~^^^^^^^^^
  File "C:\Users\kores\PycharmProjects\NewSite\NewsSite\venv\Lib\site-packages\django\template\defaulttags.py", line 327, in render
    return nodelist.render(context)
           ~~~~~~~~~~~~~~~^^^^^^^^^
  File "C:\Users\kores\PycharmProjects\NewSite\NewsSite\venv\Lib\site-packages\django\template\base.py", line 1016, in render
    return SafeString("".join([node.render_annotated(context) for node in self]))
                               ~~~~~~~~~~~~~~~~~~~~~^^^^^^^^^
  File "C:\Users\kores\PycharmProjects\NewSite\NewsSite\venv\Lib\site-packages\django\template\base.py", line 977, in render_annotated
    return self.render(context)
           ~~~~~~~~~~~^^^^^^^^^
  File "C:\Users\kores\PycharmProjects\NewSite\NewsSite\venv\Lib\site-packages\django\template\defaulttags.py", line 480, in render
    url = reverse(view_name, args=args, kwargs=kwargs, current_app=current_app)
  File "C:\Users\kores\PycharmProjects\NewSite\NewsSite\venv\Lib\site-packages\django\urls\base.py", line 98, in reverse
    resolved_url = resolver._reverse_with_prefix(view, prefix, *args, **kwargs)
  File "C:\Users\kores\PycharmProjects\NewSite\NewsSite\venv\Lib\site-packages\django\urls\resolvers.py", line 831, in _reverse_with_prefix
    raise NoReverseMatch(msg)
django.urls.exceptions.NoReverseMatch: Reverse for 'account_logout' not found. 'account_logout' is not a valid view function or pattern name.
2025-08-11 20:31:24 ERROR "GET /news/profile/ HTTP/1.1" 500 175796 C:\Users\kores\PycharmProjects\NewSite\NewsSite\venv\Lib\site-packages\django\core\servers\basehttp.py
None
2025-08-11 20:31:25 ERROR Internal Server Error: /news/ C:\Users\kores\PycharmProjects\NewSite\NewsSite\venv\Lib\site-packages\django\utils\log.py
None
Traceback (most recent call last):
  File "C:\Users\kores\PycharmProjects\NewSite\NewsSite\venv\Lib\site-packages\django\core\handlers\exception.py", line 55, in inner
    response = get_response(request)
  File "C:\Users\kores\PycharmProjects\NewSite\NewsSite\venv\Lib\site-packages\django\core\handlers\base.py", line 220, in _get_response
    response = response.render()
  File "C:\Users\kores\PycharmProjects\NewSite\NewsSite\venv\Lib\site-packages\django\template\response.py", line 114, in render
    self.content = self.rendered_content
                   ^^^^^^^^^^^^^^^^^^^^^
  File "C:\Users\kores\PycharmProjects\NewSite\NewsSite\venv\Lib\site-packages\django\template\response.py", line 92, in rendered_content
    return template.render(context, self._request)
           ~~~~~~~~~~~~~~~^^^^^^^^^^^^^^^^^^^^^^^^
  File "C:\Users\kores\PycharmProjects\NewSite\NewsSite\venv\Lib\site-packages\django\template\backends\django.py", line 107, in render
    return self.template.render(context)
           ~~~~~~~~~~~~~~~~~~~~^^^^^^^^^
  File "C:\Users\kores\PycharmProjects\NewSite\NewsSite\venv\Lib\site-packages\django\template\base.py", line 171, in render
    return self._render(context)
           ~~~~~~~~~~~~^^^^^^^^^
  File "C:\Users\kores\PycharmProjects\NewSite\NewsSite\venv\Lib\site-packages\django\template\base.py", line 163, in _render
    return self.nodelist.render(context)
           ~~~~~~~~~~~~~~~~~~~~^^^^^^^^^
  File "C:\Users\kores\PycharmProjects\NewSite\NewsSite\venv\Lib\site-packages\django\template\base.py", line 1016, in render
    return SafeString("".join([node.render_annotated(context) for node in self]))
                               ~~~~~~~~~~~~~~~~~~~~~^^^^^^^^^
  File "C:\Users\kores\PycharmProjects\NewSite\NewsSite\venv\Lib\site-packages\django\template\base.py", line 977, in render_annotated
    return self.render(context)
           ~~~~~~~~~~~^^^^^^^^^
  File "C:\Users\kores\PycharmProjects\NewSite\NewsSite\venv\Lib\site-packages\django\template\loader_tags.py", line 159, in render
    return compiled_parent._render(context)
           ~~~~~~~~~~~~~~~~~~~~~~~^^^^^^^^^
  File "C:\Users\kores\PycharmProjects\NewSite\NewsSite\venv\Lib\site-packages\django\template\base.py", line 163, in _render
    return self.nodelist.render(context)
           ~~~~~~~~~~~~~~~~~~~~^^^^^^^^^
  File "C:\Users\kores\PycharmProjects\NewSite\NewsSite\venv\Lib\site-packages\django\template\base.py", line 1016, in render
    return SafeString("".join([node.render_annotated(context) for node in self]))
                               ~~~~~~~~~~~~~~~~~~~~~^^^^^^^^^
  File "C:\Users\kores\PycharmProjects\NewSite\NewsSite\venv\Lib\site-packages\django\template\base.py", line 977, in render_annotated
    return self.render(context)
           ~~~~~~~~~~~^^^^^^^^^
  File "C:\Users\kores\PycharmProjects\NewSite\NewsSite\venv\Lib\site-packages\django\templatetags\cache.py", line 53, in render
    value = self.nodelist.render(context)
  File "C:\Users\kores\PycharmProjects\NewSite\NewsSite\venv\Lib\site-packages\django\template\base.py", line 1016, in render
    return SafeString("".join([node.render_annotated(context) for node in self]))
                               ~~~~~~~~~~~~~~~~~~~~~^^^^^^^^^
  File "C:\Users\kores\PycharmProjects\NewSite\NewsSite\venv\Lib\site-packages\django\template\base.py", line 977, in render_annotated
    return self.render(context)
           ~~~~~~~~~~~^^^^^^^^^
  File "C:\Users\kores\PycharmProjects\NewSite\NewsSite\venv\Lib\site-packages\django\template\defaulttags.py", line 327, in render
    return nodelist.render(context)
           ~~~~~~~~~~~~~~~^^^^^^^^^
  File "C:\Users\kores\PycharmProjects\NewSite\NewsSite\venv\Lib\site-packages\django\template\base.py", line 1016, in render
    return SafeString("".join([node.render_annotated(context) for node in self]))
                               ~~~~~~~~~~~~~~~~~~~~~^^^^^^^^^
  File "C:\Users\kores\PycharmProjects\NewSite\NewsSite\venv\Lib\site-packages\django\template\base.py", line 977, in render_annotated
    return self.render(context)
           ~~~~~~~~~~~^^^^^^^^^
  File "C:\Users\kores\PycharmProjects\NewSite\NewsSite\venv\Lib\site-packages\django\template\defaulttags.py", line 480, in render
    url = reverse(view_name, args=args, kwargs=kwargs, current_app=current_app)
  File "C:\Users\kores\PycharmProjects\NewSite\NewsSite\venv\Lib\site-packages\django\urls\base.py", line 98, in reverse
    resolved_url = resolver._reverse_with_prefix(view, prefix, *args, **kwargs)
  File "C:\Users\kores\PycharmProjects\NewSite\NewsSite\venv\Lib\site-packages\django\urls\resolvers.py", line 831, in _reverse_with_prefix
    raise NoReverseMatch(msg)
django.urls.exceptions.NoReverseMatch: Reverse for 'account_logout' not found. 'account_logout' is not a valid view function or pattern name.
2025-08-11 20:31:25 ERROR "GET /news/ HTTP/1.1" 500 188984 C:\Users\kores\PycharmProjects\NewSite\NewsSite\venv\Lib\site-packages\django\core\servers\basehttp.py
None
2025-08-11 20:31:33 ERROR Internal Server Error: /news/ C:\Users\kores\PycharmProjects\NewSite\NewsSite\venv\Lib\site-packages\django\utils\log.py
None
Traceback (most recent call last):
  File "C:\Users\kores\PycharmProjects\NewSite\NewsSite\venv\Lib\site-packages\django\core\handlers\exception.py", line 55, in inner
    response = get_response(request)
  File "C:\Users\kores\PycharmProjects\NewSite\NewsSite\venv\Lib\site-packages\django\core\handlers\base.py", line 220, in _get_response
    response = response.render()
  File "C:\Users\kores\PycharmProjects\NewSite\NewsSite\venv\Lib\site-packages\django\template\response.py", line 114, in render
    self.content = self.rendered_content
                   ^^^^^^^^^^^^^^^^^^^^^
  File "C:\Users\kores\PycharmProjects\NewSite\NewsSite\venv\Lib\site-packages\django\template\response.py", line 92, in rendered_content
    return template.render(context, self._request)
           ~~~~~~~~~~~~~~~^^^^^^^^^^^^^^^^^^^^^^^^
  File "C:\Users\kores\PycharmProjects\NewSite\NewsSite\venv\Lib\site-packages\django\template\backends\django.py", line 107, in render
    return self.template.render(context)
           ~~~~~~~~~~~~~~~~~~~~^^^^^^^^^
  File "C:\Users\kores\PycharmProjects\NewSite\NewsSite\venv\Lib\site-packages\django\template\base.py", line 171, in render
    return self._render(context)
           ~~~~~~~~~~~~^^^^^^^^^
  File "C:\Users\kores\PycharmProjects\NewSite\NewsSite\venv\Lib\site-packages\django\template\base.py", line 163, in _render
    return self.nodelist.render(context)
           ~~~~~~~~~~~~~~~~~~~~^^^^^^^^^
  File "C:\Users\kores\PycharmProjects\NewSite\NewsSite\venv\Lib\site-packages\django\template\base.py", line 1016, in render
    return SafeString("".join([node.render_annotated(context) for node in self]))
                               ~~~~~~~~~~~~~~~~~~~~~^^^^^^^^^
  File "C:\Users\kores\PycharmProjects\NewSite\NewsSite\venv\Lib\site-packages\django\template\base.py", line 977, in render_annotated
    return self.render(context)
           ~~~~~~~~~~~^^^^^^^^^
  File "C:\Users\kores\PycharmProjects\NewSite\NewsSite\venv\Lib\site-packages\django\template\loader_tags.py", line 159, in render
    return compiled_parent._render(context)
           ~~~~~~~~~~~~~~~~~~~~~~~^^^^^^^^^
  File "C:\Users\kores\PycharmProjects\NewSite\NewsSite\venv\Lib\site-packages\django\template\base.py", line 163, in _render
    return self.nodelist.render(context)
           ~~~~~~~~~~~~~~~~~~~~^^^^^^^^^
  File "C:\Users\kores\PycharmProjects\NewSite\NewsSite\venv\Lib\site-packages\django\template\base.py", line 1016, in render
    return SafeString("".join([node.render_annotated(context) for node in self]))
                               ~~~~~~~~~~~~~~~~~~~~~^^^^^^^^^
  File "C:\Users\kores\PycharmProjects\NewSite\NewsSite\venv\Lib\site-packages\django\template\base.py", line 977, in render_annotated
    return self.render(context)
           ~~~~~~~~~~~^^^^^^^^^
  File "C:\Users\kores\PycharmProjects\NewSite\NewsSite\venv\Lib\site-packages\django\templatetags\cache.py", line 53, in render
    value = self.nodelist.render(context)
  File "C:\Users\kores\PycharmProjects\NewSite\NewsSite\venv\Lib\site-packages\django\template\base.py", line 1016, in render
    return SafeString("".join([node.render_annotated(context) for node in self]))
                               ~~~~~~~~~~~~~~~~~~~~~^^^^^^^^^
  File "C:\Users\kores\PycharmProjects\NewSite\NewsSite\venv\Lib\site-packages\django\template\base.py", line 977, in render_annotated
    return self.render(context)
           ~~~~~~~~~~~^^^^^^^^^
  File "C:\Users\kores\PycharmProjects\NewSite\NewsSite\venv\Lib\site-packages\django\template\defaulttags.py", line 327, in render
    return nodelist.render(context)
           ~~~~~~~~~~~~~~~^^^^^^^^^
  File "C:\Users\kores\PycharmProjects\NewSite\NewsSite\venv\Lib\site-packages\django\template\base.py", line 1016, in render
    return SafeString("".join([node.render_annotated(context) for node in self]))
                               ~~~~~~~~~~~~~~~~~~~~~^^^^^^^^^
  File "C:\Users\kores\PycharmProjects\NewSite\NewsSite\venv\Lib\site-packages\django\template\base.py", line 977, in render_annotated
    return self.render(context)
           ~~~~~~~~~~~^^^^^^^^^
  File "C:\Users\kores\PycharmProjects\NewSite\NewsSite\venv\Lib\site-packages\django\template\defaulttags.py", line 480, in render
    url = reverse(view_name, args=args, kwargs=kwargs, current_app=current_app)
  File "C:\Users\kores\PycharmProjects\NewSite\NewsSite\venv\Lib\site-packages\django\urls\base.py", line 98, in reverse
    resolved_url = resolver._reverse_with_prefix(view, prefix, *args, **kwargs)
  File "C:\Users\kores\PycharmProjects\NewSite\NewsSite\venv\Lib\site-packages\django\urls\resolvers.py", line 831, in _reverse_with_prefix
    raise NoReverseMatch(msg)
django.urls.exceptions.NoReverseMatch: Reverse for 'account_logout' not found. 'account_logout' is not a valid view function or pattern name.
2025-08-11 20:31:33 ERROR "GET /news/ HTTP/1.1" 500 188984 C:\Users\kores\PycharmProjects\NewSite\NewsSite\venv\Lib\site-packages\django\core\servers\basehttp.py
None
2025-08-11 20:57:09 ERROR Internal Server Error: / C:\Users\kores\PycharmProjects\NewSite\NewsSite\venv\Lib\site-packages\django\utils\log.py
None
Traceback (most recent call last):
  File "C:\Users\kores\PycharmProjects\NewSite\NewsSite\venv\Lib\site-packages\django\contrib\sessions\backends\base.py", line 244, in _get_session
    return self._session_cache
           ^^^^^^^^^^^^^^^^^^^
AttributeError: 'SessionStore' object has no attribute '_session_cache'

During handling of the above exception, another exception occurred:

Traceback (most recent call last):
  File "C:\Users\kores\PycharmProjects\NewSite\NewsSite\venv\Lib\site-packages\redis\connection.py", line 357, in connect
    sock = self.retry.call_with_retry(
        lambda: self._connect(), lambda error: self.disconnect(error)
    )
  File "C:\Users\kores\PycharmProjects\NewSite\NewsSite\venv\Lib\site-packages\redis\retry.py", line 62, in call_with_retry
    return do()
  File "C:\Users\kores\PycharmProjects\NewSite\NewsSite\venv\Lib\site-packages\redis\connection.py", line 358, in <lambda>
    lambda: self._connect(), lambda error: self.disconnect(error)
            ~~~~~~~~~~~~~^^
  File "C:\Users\kores\PycharmProjects\NewSite\NewsSite\venv\Lib\site-packages\redis\connection.py", line 730, in _connect
    raise err
  File "C:\Users\kores\PycharmProjects\NewSite\NewsSite\venv\Lib\site-packages\redis\connection.py", line 718, in _connect
    sock.connect(socket_address)
    ~~~~~~~~~~~~^^^^^^^^^^^^^^^^
ConnectionRefusedError: [WinError 10061] Подключение не установлено, т.к. конечный компьютер отверг запрос на подключение

During handling of the above exception, another exception occurred:

Traceback (most recent call last):
  File "C:\Users\kores\PycharmProjects\NewSite\NewsSite\venv\Lib\site-packages\django\core\handlers\exception.py", line 55, in inner
    response = get_response(request)
  File "C:\Users\kores\PycharmProjects\NewSite\NewsSite\venv\Lib\site-packages\django\utils\deprecation.py", line 119, in __call__
    response = self.process_request(request)
  File "C:\Users\kores\PycharmProjects\NewSite\NewsSite\news\middleware.py", line 7, in process_request
    if hasattr(request.user, 'userprofile'):
       ~~~~~~~^^^^^^^^^^^^^^^^^^^^^^^^^^^^^
  File "C:\Users\kores\PycharmProjects\NewSite\NewsSite\venv\Lib\site-packages\django\utils\functional.py", line 251, in inner
    self._setup()
    ~~~~~~~~~~~^^
  File "C:\Users\kores\PycharmProjects\NewSite\NewsSite\venv\Lib\site-packages\django\utils\functional.py", line 404, in _setup
    self._wrapped = self._setupfunc()
                    ~~~~~~~~~~~~~~~^^
  File "C:\Users\kores\PycharmProjects\NewSite\NewsSite\venv\Lib\site-packages\django\contrib\auth\middleware.py", line 40, in <lambda>
    request.user = SimpleLazyObject(lambda: get_user(request))
                                            ~~~~~~~~^^^^^^^^^
  File "C:\Users\kores\PycharmProjects\NewSite\NewsSite\venv\Lib\site-packages\django\contrib\auth\middleware.py", line 20, in get_user
    request._cached_user = auth.get_user(request)
                           ~~~~~~~~~~~~~^^^^^^^^^
  File "C:\Users\kores\PycharmProjects\NewSite\NewsSite\venv\Lib\site-packages\django\contrib\auth\__init__.py", line 304, in get_user
    user_id = _get_user_session_key(request)
  File "C:\Users\kores\PycharmProjects\NewSite\NewsSite\venv\Lib\site-packages\django\contrib\auth\__init__.py", line 95, in _get_user_session_key
    return get_user_model()._meta.pk.to_python(request.session[SESSION_KEY])
                                               ~~~~~~~~~~~~~~~^^^^^^^^^^^^^
  File "C:\Users\kores\PycharmProjects\NewSite\NewsSite\venv\Lib\site-packages\django\contrib\sessions\backends\base.py", line 55, in __getitem__
    return self._session[key]
           ^^^^^^^^^^^^^
  File "C:\Users\kores\PycharmProjects\NewSite\NewsSite\venv\Lib\site-packages\django\contrib\sessions\backends\base.py", line 249, in _get_session
    self._session_cache = self.load()
                          ~~~~~~~~~^^
  File "C:\Users\kores\PycharmProjects\NewSite\NewsSite\venv\Lib\site-packages\django\contrib\sessions\backends\cached_db.py", line 46, in load
    self._cache.set(
    ~~~~~~~~~~~~~~~^
        self.cache_key, data, self.get_expiry_age(expiry=s.expire_date)
        ^^^^^^^^^^^^^^^^^^^^^^^^^^^^^^^^^^^^^^^^^^^^^^^^^^^^^^^^^^^^^^^
    )
    ^
  File "C:\Users\kores\PycharmProjects\NewSite\NewsSite\venv\Lib\site-packages\django\core\cache\backends\redis.py", line 192, in set
    self._cache.set(key, value, self.get_backend_timeout(timeout))
    ~~~~~~~~~~~~~~~^^^^^^^^^^^^^^^^^^^^^^^^^^^^^^^^^^^^^^^^^^^^^^^
  File "C:\Users\kores\PycharmProjects\NewSite\NewsSite\venv\Lib\site-packages\django\core\cache\backends\redis.py", line 109, in set
    client.set(key, value, ex=timeout)
    ~~~~~~~~~~^^^^^^^^^^^^^^^^^^^^^^^^
  File "C:\Users\kores\PycharmProjects\NewSite\NewsSite\venv\Lib\site-packages\redis\commands\core.py", line 2335, in set
    return self.execute_command("SET", *pieces, **options)
           ~~~~~~~~~~~~~~~~~~~~^^^^^^^^^^^^^^^^^^^^^^^^^^^
  File "C:\Users\kores\PycharmProjects\NewSite\NewsSite\venv\Lib\site-packages\redis\client.py", line 559, in execute_command
    return self._execute_command(*args, **options)
           ~~~~~~~~~~~~~~~~~~~~~^^^^^^^^^^^^^^^^^^
  File "C:\Users\kores\PycharmProjects\NewSite\NewsSite\venv\Lib\site-packages\redis\client.py", line 565, in _execute_command
    conn = self.connection or pool.get_connection(command_name, **options)
                              ~~~~~~~~~~~~~~~~~~~^^^^^^^^^^^^^^^^^^^^^^^^^
  File "C:\Users\kores\PycharmProjects\NewSite\NewsSite\venv\Lib\site-packages\redis\connection.py", line 1422, in get_connection
    connection.connect()
    ~~~~~~~~~~~~~~~~~~^^
  File "C:\Users\kores\PycharmProjects\NewSite\NewsSite\venv\Lib\site-packages\redis\connection.py", line 363, in connect
    raise ConnectionError(self._error_message(e))
redis.exceptions.ConnectionError: Error 10061 connecting to 127.0.0.1:6379. Подключение не установлено, т.к. конечный компьютер отверг запрос на подключение.
2025-08-11 20:57:34 ERROR Internal Server Error: /52/ C:\Users\kores\PycharmProjects\NewSite\NewsSite\venv\Lib\site-packages\django\utils\log.py
None
Traceback (most recent call last):
  File "C:\Users\kores\PycharmProjects\NewSite\NewsSite\venv\Lib\site-packages\django\contrib\sessions\backends\base.py", line 244, in _get_session
    return self._session_cache
           ^^^^^^^^^^^^^^^^^^^
AttributeError: 'SessionStore' object has no attribute '_session_cache'

During handling of the above exception, another exception occurred:

Traceback (most recent call last):
  File "C:\Users\kores\PycharmProjects\NewSite\NewsSite\venv\Lib\site-packages\redis\connection.py", line 357, in connect
    sock = self.retry.call_with_retry(
        lambda: self._connect(), lambda error: self.disconnect(error)
    )
  File "C:\Users\kores\PycharmProjects\NewSite\NewsSite\venv\Lib\site-packages\redis\retry.py", line 62, in call_with_retry
    return do()
  File "C:\Users\kores\PycharmProjects\NewSite\NewsSite\venv\Lib\site-packages\redis\connection.py", line 358, in <lambda>
    lambda: self._connect(), lambda error: self.disconnect(error)
            ~~~~~~~~~~~~~^^
  File "C:\Users\kores\PycharmProjects\NewSite\NewsSite\venv\Lib\site-packages\redis\connection.py", line 730, in _connect
    raise err
  File "C:\Users\kores\PycharmProjects\NewSite\NewsSite\venv\Lib\site-packages\redis\connection.py", line 718, in _connect
    sock.connect(socket_address)
    ~~~~~~~~~~~~^^^^^^^^^^^^^^^^
ConnectionRefusedError: [WinError 10061] Подключение не установлено, т.к. конечный компьютер отверг запрос на подключение

During handling of the above exception, another exception occurred:

Traceback (most recent call last):
  File "C:\Users\kores\PycharmProjects\NewSite\NewsSite\venv\Lib\site-packages\django\core\handlers\exception.py", line 55, in inner
    response = get_response(request)
  File "C:\Users\kores\PycharmProjects\NewSite\NewsSite\venv\Lib\site-packages\django\utils\deprecation.py", line 119, in __call__
    response = self.process_request(request)
  File "C:\Users\kores\PycharmProjects\NewSite\NewsSite\news\middleware.py", line 7, in process_request
    if hasattr(request.user, 'userprofile'):
       ~~~~~~~^^^^^^^^^^^^^^^^^^^^^^^^^^^^^
  File "C:\Users\kores\PycharmProjects\NewSite\NewsSite\venv\Lib\site-packages\django\utils\functional.py", line 251, in inner
    self._setup()
    ~~~~~~~~~~~^^
  File "C:\Users\kores\PycharmProjects\NewSite\NewsSite\venv\Lib\site-packages\django\utils\functional.py", line 404, in _setup
    self._wrapped = self._setupfunc()
                    ~~~~~~~~~~~~~~~^^
  File "C:\Users\kores\PycharmProjects\NewSite\NewsSite\venv\Lib\site-packages\django\contrib\auth\middleware.py", line 40, in <lambda>
    request.user = SimpleLazyObject(lambda: get_user(request))
                                            ~~~~~~~~^^^^^^^^^
  File "C:\Users\kores\PycharmProjects\NewSite\NewsSite\venv\Lib\site-packages\django\contrib\auth\middleware.py", line 20, in get_user
    request._cached_user = auth.get_user(request)
                           ~~~~~~~~~~~~~^^^^^^^^^
  File "C:\Users\kores\PycharmProjects\NewSite\NewsSite\venv\Lib\site-packages\django\contrib\auth\__init__.py", line 304, in get_user
    user_id = _get_user_session_key(request)
  File "C:\Users\kores\PycharmProjects\NewSite\NewsSite\venv\Lib\site-packages\django\contrib\auth\__init__.py", line 95, in _get_user_session_key
    return get_user_model()._meta.pk.to_python(request.session[SESSION_KEY])
                                               ~~~~~~~~~~~~~~~^^^^^^^^^^^^^
  File "C:\Users\kores\PycharmProjects\NewSite\NewsSite\venv\Lib\site-packages\django\contrib\sessions\backends\base.py", line 55, in __getitem__
    return self._session[key]
           ^^^^^^^^^^^^^
  File "C:\Users\kores\PycharmProjects\NewSite\NewsSite\venv\Lib\site-packages\django\contrib\sessions\backends\base.py", line 249, in _get_session
    self._session_cache = self.load()
                          ~~~~~~~~~^^
  File "C:\Users\kores\PycharmProjects\NewSite\NewsSite\venv\Lib\site-packages\django\contrib\sessions\backends\cached_db.py", line 46, in load
    self._cache.set(
    ~~~~~~~~~~~~~~~^
        self.cache_key, data, self.get_expiry_age(expiry=s.expire_date)
        ^^^^^^^^^^^^^^^^^^^^^^^^^^^^^^^^^^^^^^^^^^^^^^^^^^^^^^^^^^^^^^^
    )
    ^
  File "C:\Users\kores\PycharmProjects\NewSite\NewsSite\venv\Lib\site-packages\django\core\cache\backends\redis.py", line 192, in set
    self._cache.set(key, value, self.get_backend_timeout(timeout))
    ~~~~~~~~~~~~~~~^^^^^^^^^^^^^^^^^^^^^^^^^^^^^^^^^^^^^^^^^^^^^^^
  File "C:\Users\kores\PycharmProjects\NewSite\NewsSite\venv\Lib\site-packages\django\core\cache\backends\redis.py", line 109, in set
    client.set(key, value, ex=timeout)
    ~~~~~~~~~~^^^^^^^^^^^^^^^^^^^^^^^^
  File "C:\Users\kores\PycharmProjects\NewSite\NewsSite\venv\Lib\site-packages\redis\commands\core.py", line 2335, in set
    return self.execute_command("SET", *pieces, **options)
           ~~~~~~~~~~~~~~~~~~~~^^^^^^^^^^^^^^^^^^^^^^^^^^^
  File "C:\Users\kores\PycharmProjects\NewSite\NewsSite\venv\Lib\site-packages\redis\client.py", line 559, in execute_command
    return self._execute_command(*args, **options)
           ~~~~~~~~~~~~~~~~~~~~~^^^^^^^^^^^^^^^^^^
  File "C:\Users\kores\PycharmProjects\NewSite\NewsSite\venv\Lib\site-packages\redis\client.py", line 565, in _execute_command
    conn = self.connection or pool.get_connection(command_name, **options)
                              ~~~~~~~~~~~~~~~~~~~^^^^^^^^^^^^^^^^^^^^^^^^^
  File "C:\Users\kores\PycharmProjects\NewSite\NewsSite\venv\Lib\site-packages\redis\connection.py", line 1422, in get_connection
    connection.connect()
    ~~~~~~~~~~~~~~~~~~^^
  File "C:\Users\kores\PycharmProjects\NewSite\NewsSite\venv\Lib\site-packages\redis\connection.py", line 363, in connect
    raise ConnectionError(self._error_message(e))
redis.exceptions.ConnectionError: Error 10061 connecting to 127.0.0.1:6379. Подключение не установлено, т.к. конечный компьютер отверг запрос на подключение.
2025-08-11 20:57:37 ERROR Internal Server Error: /52/ C:\Users\kores\PycharmProjects\NewSite\NewsSite\venv\Lib\site-packages\django\utils\log.py
None
Traceback (most recent call last):
  File "C:\Users\kores\PycharmProjects\NewSite\NewsSite\venv\Lib\site-packages\django\contrib\sessions\backends\base.py", line 244, in _get_session
    return self._session_cache
           ^^^^^^^^^^^^^^^^^^^
AttributeError: 'SessionStore' object has no attribute '_session_cache'

During handling of the above exception, another exception occurred:

Traceback (most recent call last):
  File "C:\Users\kores\PycharmProjects\NewSite\NewsSite\venv\Lib\site-packages\redis\connection.py", line 357, in connect
    sock = self.retry.call_with_retry(
        lambda: self._connect(), lambda error: self.disconnect(error)
    )
  File "C:\Users\kores\PycharmProjects\NewSite\NewsSite\venv\Lib\site-packages\redis\retry.py", line 62, in call_with_retry
    return do()
  File "C:\Users\kores\PycharmProjects\NewSite\NewsSite\venv\Lib\site-packages\redis\connection.py", line 358, in <lambda>
    lambda: self._connect(), lambda error: self.disconnect(error)
            ~~~~~~~~~~~~~^^
  File "C:\Users\kores\PycharmProjects\NewSite\NewsSite\venv\Lib\site-packages\redis\connection.py", line 730, in _connect
    raise err
  File "C:\Users\kores\PycharmProjects\NewSite\NewsSite\venv\Lib\site-packages\redis\connection.py", line 718, in _connect
    sock.connect(socket_address)
    ~~~~~~~~~~~~^^^^^^^^^^^^^^^^
ConnectionRefusedError: [WinError 10061] Подключение не установлено, т.к. конечный компьютер отверг запрос на подключение

During handling of the above exception, another exception occurred:

Traceback (most recent call last):
  File "C:\Users\kores\PycharmProjects\NewSite\NewsSite\venv\Lib\site-packages\django\core\handlers\exception.py", line 55, in inner
    response = get_response(request)
  File "C:\Users\kores\PycharmProjects\NewSite\NewsSite\venv\Lib\site-packages\django\utils\deprecation.py", line 119, in __call__
    response = self.process_request(request)
  File "C:\Users\kores\PycharmProjects\NewSite\NewsSite\news\middleware.py", line 7, in process_request
    if hasattr(request.user, 'userprofile'):
       ~~~~~~~^^^^^^^^^^^^^^^^^^^^^^^^^^^^^
  File "C:\Users\kores\PycharmProjects\NewSite\NewsSite\venv\Lib\site-packages\django\utils\functional.py", line 251, in inner
    self._setup()
    ~~~~~~~~~~~^^
  File "C:\Users\kores\PycharmProjects\NewSite\NewsSite\venv\Lib\site-packages\django\utils\functional.py", line 404, in _setup
    self._wrapped = self._setupfunc()
                    ~~~~~~~~~~~~~~~^^
  File "C:\Users\kores\PycharmProjects\NewSite\NewsSite\venv\Lib\site-packages\django\contrib\auth\middleware.py", line 40, in <lambda>
    request.user = SimpleLazyObject(lambda: get_user(request))
                                            ~~~~~~~~^^^^^^^^^
  File "C:\Users\kores\PycharmProjects\NewSite\NewsSite\venv\Lib\site-packages\django\contrib\auth\middleware.py", line 20, in get_user
    request._cached_user = auth.get_user(request)
                           ~~~~~~~~~~~~~^^^^^^^^^
  File "C:\Users\kores\PycharmProjects\NewSite\NewsSite\venv\Lib\site-packages\django\contrib\auth\__init__.py", line 304, in get_user
    user_id = _get_user_session_key(request)
  File "C:\Users\kores\PycharmProjects\NewSite\NewsSite\venv\Lib\site-packages\django\contrib\auth\__init__.py", line 95, in _get_user_session_key
    return get_user_model()._meta.pk.to_python(request.session[SESSION_KEY])
                                               ~~~~~~~~~~~~~~~^^^^^^^^^^^^^
  File "C:\Users\kores\PycharmProjects\NewSite\NewsSite\venv\Lib\site-packages\django\contrib\sessions\backends\base.py", line 55, in __getitem__
    return self._session[key]
           ^^^^^^^^^^^^^
  File "C:\Users\kores\PycharmProjects\NewSite\NewsSite\venv\Lib\site-packages\django\contrib\sessions\backends\base.py", line 249, in _get_session
    self._session_cache = self.load()
                          ~~~~~~~~~^^
  File "C:\Users\kores\PycharmProjects\NewSite\NewsSite\venv\Lib\site-packages\django\contrib\sessions\backends\cached_db.py", line 46, in load
    self._cache.set(
    ~~~~~~~~~~~~~~~^
        self.cache_key, data, self.get_expiry_age(expiry=s.expire_date)
        ^^^^^^^^^^^^^^^^^^^^^^^^^^^^^^^^^^^^^^^^^^^^^^^^^^^^^^^^^^^^^^^
    )
    ^
  File "C:\Users\kores\PycharmProjects\NewSite\NewsSite\venv\Lib\site-packages\django\core\cache\backends\redis.py", line 192, in set
    self._cache.set(key, value, self.get_backend_timeout(timeout))
    ~~~~~~~~~~~~~~~^^^^^^^^^^^^^^^^^^^^^^^^^^^^^^^^^^^^^^^^^^^^^^^
  File "C:\Users\kores\PycharmProjects\NewSite\NewsSite\venv\Lib\site-packages\django\core\cache\backends\redis.py", line 109, in set
    client.set(key, value, ex=timeout)
    ~~~~~~~~~~^^^^^^^^^^^^^^^^^^^^^^^^
  File "C:\Users\kores\PycharmProjects\NewSite\NewsSite\venv\Lib\site-packages\redis\commands\core.py", line 2335, in set
    return self.execute_command("SET", *pieces, **options)
           ~~~~~~~~~~~~~~~~~~~~^^^^^^^^^^^^^^^^^^^^^^^^^^^
  File "C:\Users\kores\PycharmProjects\NewSite\NewsSite\venv\Lib\site-packages\redis\client.py", line 559, in execute_command
    return self._execute_command(*args, **options)
           ~~~~~~~~~~~~~~~~~~~~~^^^^^^^^^^^^^^^^^^
  File "C:\Users\kores\PycharmProjects\NewSite\NewsSite\venv\Lib\site-packages\redis\client.py", line 565, in _execute_command
    conn = self.connection or pool.get_connection(command_name, **options)
                              ~~~~~~~~~~~~~~~~~~~^^^^^^^^^^^^^^^^^^^^^^^^^
  File "C:\Users\kores\PycharmProjects\NewSite\NewsSite\venv\Lib\site-packages\redis\connection.py", line 1422, in get_connection
    connection.connect()
    ~~~~~~~~~~~~~~~~~~^^
  File "C:\Users\kores\PycharmProjects\NewSite\NewsSite\venv\Lib\site-packages\redis\connection.py", line 363, in connect
    raise ConnectionError(self._error_message(e))
redis.exceptions.ConnectionError: Error 10061 connecting to 127.0.0.1:6379. Подключение не установлено, т.к. конечный компьютер отверг запрос на подключение.
2025-08-11 20:57:43 ERROR Internal Server Error: / C:\Users\kores\PycharmProjects\NewSite\NewsSite\venv\Lib\site-packages\django\utils\log.py
None
Traceback (most recent call last):
  File "C:\Users\kores\PycharmProjects\NewSite\NewsSite\venv\Lib\site-packages\django\contrib\sessions\backends\base.py", line 244, in _get_session
    return self._session_cache
           ^^^^^^^^^^^^^^^^^^^
AttributeError: 'SessionStore' object has no attribute '_session_cache'

During handling of the above exception, another exception occurred:

Traceback (most recent call last):
  File "C:\Users\kores\PycharmProjects\NewSite\NewsSite\venv\Lib\site-packages\redis\connection.py", line 357, in connect
    sock = self.retry.call_with_retry(
        lambda: self._connect(), lambda error: self.disconnect(error)
    )
  File "C:\Users\kores\PycharmProjects\NewSite\NewsSite\venv\Lib\site-packages\redis\retry.py", line 62, in call_with_retry
    return do()
  File "C:\Users\kores\PycharmProjects\NewSite\NewsSite\venv\Lib\site-packages\redis\connection.py", line 358, in <lambda>
    lambda: self._connect(), lambda error: self.disconnect(error)
            ~~~~~~~~~~~~~^^
  File "C:\Users\kores\PycharmProjects\NewSite\NewsSite\venv\Lib\site-packages\redis\connection.py", line 730, in _connect
    raise err
  File "C:\Users\kores\PycharmProjects\NewSite\NewsSite\venv\Lib\site-packages\redis\connection.py", line 718, in _connect
    sock.connect(socket_address)
    ~~~~~~~~~~~~^^^^^^^^^^^^^^^^
ConnectionRefusedError: [WinError 10061] Подключение не установлено, т.к. конечный компьютер отверг запрос на подключение

During handling of the above exception, another exception occurred:

Traceback (most recent call last):
  File "C:\Users\kores\PycharmProjects\NewSite\NewsSite\venv\Lib\site-packages\django\core\handlers\exception.py", line 55, in inner
    response = get_response(request)
  File "C:\Users\kores\PycharmProjects\NewSite\NewsSite\venv\Lib\site-packages\django\utils\deprecation.py", line 119, in __call__
    response = self.process_request(request)
  File "C:\Users\kores\PycharmProjects\NewSite\NewsSite\news\middleware.py", line 7, in process_request
    if hasattr(request.user, 'userprofile'):
       ~~~~~~~^^^^^^^^^^^^^^^^^^^^^^^^^^^^^
  File "C:\Users\kores\PycharmProjects\NewSite\NewsSite\venv\Lib\site-packages\django\utils\functional.py", line 251, in inner
    self._setup()
    ~~~~~~~~~~~^^
  File "C:\Users\kores\PycharmProjects\NewSite\NewsSite\venv\Lib\site-packages\django\utils\functional.py", line 404, in _setup
    self._wrapped = self._setupfunc()
                    ~~~~~~~~~~~~~~~^^
  File "C:\Users\kores\PycharmProjects\NewSite\NewsSite\venv\Lib\site-packages\django\contrib\auth\middleware.py", line 40, in <lambda>
    request.user = SimpleLazyObject(lambda: get_user(request))
                                            ~~~~~~~~^^^^^^^^^
  File "C:\Users\kores\PycharmProjects\NewSite\NewsSite\venv\Lib\site-packages\django\contrib\auth\middleware.py", line 20, in get_user
    request._cached_user = auth.get_user(request)
                           ~~~~~~~~~~~~~^^^^^^^^^
  File "C:\Users\kores\PycharmProjects\NewSite\NewsSite\venv\Lib\site-packages\django\contrib\auth\__init__.py", line 304, in get_user
    user_id = _get_user_session_key(request)
  File "C:\Users\kores\PycharmProjects\NewSite\NewsSite\venv\Lib\site-packages\django\contrib\auth\__init__.py", line 95, in _get_user_session_key
    return get_user_model()._meta.pk.to_python(request.session[SESSION_KEY])
                                               ~~~~~~~~~~~~~~~^^^^^^^^^^^^^
  File "C:\Users\kores\PycharmProjects\NewSite\NewsSite\venv\Lib\site-packages\django\contrib\sessions\backends\base.py", line 55, in __getitem__
    return self._session[key]
           ^^^^^^^^^^^^^
  File "C:\Users\kores\PycharmProjects\NewSite\NewsSite\venv\Lib\site-packages\django\contrib\sessions\backends\base.py", line 249, in _get_session
    self._session_cache = self.load()
                          ~~~~~~~~~^^
  File "C:\Users\kores\PycharmProjects\NewSite\NewsSite\venv\Lib\site-packages\django\contrib\sessions\backends\cached_db.py", line 46, in load
    self._cache.set(
    ~~~~~~~~~~~~~~~^
        self.cache_key, data, self.get_expiry_age(expiry=s.expire_date)
        ^^^^^^^^^^^^^^^^^^^^^^^^^^^^^^^^^^^^^^^^^^^^^^^^^^^^^^^^^^^^^^^
    )
    ^
  File "C:\Users\kores\PycharmProjects\NewSite\NewsSite\venv\Lib\site-packages\django\core\cache\backends\redis.py", line 192, in set
    self._cache.set(key, value, self.get_backend_timeout(timeout))
    ~~~~~~~~~~~~~~~^^^^^^^^^^^^^^^^^^^^^^^^^^^^^^^^^^^^^^^^^^^^^^^
  File "C:\Users\kores\PycharmProjects\NewSite\NewsSite\venv\Lib\site-packages\django\core\cache\backends\redis.py", line 109, in set
    client.set(key, value, ex=timeout)
    ~~~~~~~~~~^^^^^^^^^^^^^^^^^^^^^^^^
  File "C:\Users\kores\PycharmProjects\NewSite\NewsSite\venv\Lib\site-packages\redis\commands\core.py", line 2335, in set
    return self.execute_command("SET", *pieces, **options)
           ~~~~~~~~~~~~~~~~~~~~^^^^^^^^^^^^^^^^^^^^^^^^^^^
  File "C:\Users\kores\PycharmProjects\NewSite\NewsSite\venv\Lib\site-packages\redis\client.py", line 559, in execute_command
    return self._execute_command(*args, **options)
           ~~~~~~~~~~~~~~~~~~~~~^^^^^^^^^^^^^^^^^^
  File "C:\Users\kores\PycharmProjects\NewSite\NewsSite\venv\Lib\site-packages\redis\client.py", line 565, in _execute_command
    conn = self.connection or pool.get_connection(command_name, **options)
                              ~~~~~~~~~~~~~~~~~~~^^^^^^^^^^^^^^^^^^^^^^^^^
  File "C:\Users\kores\PycharmProjects\NewSite\NewsSite\venv\Lib\site-packages\redis\connection.py", line 1422, in get_connection
    connection.connect()
    ~~~~~~~~~~~~~~~~~~^^
  File "C:\Users\kores\PycharmProjects\NewSite\NewsSite\venv\Lib\site-packages\redis\connection.py", line 363, in connect
    raise ConnectionError(self._error_message(e))
redis.exceptions.ConnectionError: Error 10061 connecting to 127.0.0.1:6379. Подключение не установлено, т.к. конечный компьютер отверг запрос на подключение.
2025-08-11 20:57:43 ERROR "GET / HTTP/1.1" 500 171970 C:\Users\kores\PycharmProjects\NewSite\NewsSite\venv\Lib\site-packages\django\core\servers\basehttp.py
None
2025-08-11 21:00:48 ERROR Internal Server Error: / C:\Users\kores\PycharmProjects\NewSite\NewsSite\venv\Lib\site-packages\django\utils\log.py
None
Traceback (most recent call last):
  File "C:\Users\kores\PycharmProjects\NewSite\NewsSite\venv\Lib\site-packages\django\utils\module_loading.py", line 30, in import_string
    return cached_import(module_path, class_name)
  File "C:\Users\kores\PycharmProjects\NewSite\NewsSite\venv\Lib\site-packages\django\utils\module_loading.py", line 16, in cached_import
    return getattr(module, class_name)
AttributeError: module 'news.context_processors' has no attribute 'theme_context'. Did you mean: 'timezone_context'?

The above exception was the direct cause of the following exception:

Traceback (most recent call last):
  File "C:\Users\kores\PycharmProjects\NewSite\NewsSite\venv\Lib\site-packages\django\core\handlers\exception.py", line 55, in inner
    response = get_response(request)
  File "C:\Users\kores\PycharmProjects\NewSite\NewsSite\venv\Lib\site-packages\django\core\handlers\base.py", line 220, in _get_response
    response = response.render()
  File "C:\Users\kores\PycharmProjects\NewSite\NewsSite\venv\Lib\site-packages\django\template\response.py", line 114, in render
    self.content = self.rendered_content
                   ^^^^^^^^^^^^^^^^^^^^^
  File "C:\Users\kores\PycharmProjects\NewSite\NewsSite\venv\Lib\site-packages\django\template\response.py", line 92, in rendered_content
    return template.render(context, self._request)
           ~~~~~~~~~~~~~~~^^^^^^^^^^^^^^^^^^^^^^^^
  File "C:\Users\kores\PycharmProjects\NewSite\NewsSite\venv\Lib\site-packages\django\template\backends\django.py", line 107, in render
    return self.template.render(context)
           ~~~~~~~~~~~~~~~~~~~~^^^^^^^^^
  File "C:\Users\kores\PycharmProjects\NewSite\NewsSite\venv\Lib\site-packages\django\template\base.py", line 169, in render
    with context.bind_template(self):
         ~~~~~~~~~~~~~~~~~~~~~^^^^^^
  File "C:\Users\kores\AppData\Local\Programs\Python\Python313\Lib\contextlib.py", line 141, in __enter__
    return next(self.gen)
  File "C:\Users\kores\PycharmProjects\NewSite\NewsSite\venv\Lib\site-packages\django\template\context.py", line 256, in bind_template
    processors = template.engine.template_context_processors + self._processors
                 ^^^^^^^^^^^^^^^^^^^^^^^^^^^^^^^^^^^^^^^^^^^
  File "C:\Users\kores\PycharmProjects\NewSite\NewsSite\venv\Lib\site-packages\django\utils\functional.py", line 47, in __get__
    res = instance.__dict__[self.name] = self.func(instance)
                                         ~~~~~~~~~^^^^^^^^^^
  File "C:\Users\kores\PycharmProjects\NewSite\NewsSite\venv\Lib\site-packages\django\template\engine.py", line 118, in template_context_processors
    return tuple(import_string(path) for path in context_processors)
  File "C:\Users\kores\PycharmProjects\NewSite\NewsSite\venv\Lib\site-packages\django\template\engine.py", line 118, in <genexpr>
    return tuple(import_string(path) for path in context_processors)
                 ~~~~~~~~~~~~~^^^^^^
  File "C:\Users\kores\PycharmProjects\NewSite\NewsSite\venv\Lib\site-packages\django\utils\module_loading.py", line 32, in import_string
    raise ImportError(
    ...<2 lines>...
    ) from err
ImportError: Module "news.context_processors" does not define a "theme_context" attribute/class
2025-08-11 21:00:48 ERROR "GET / HTTP/1.1" 500 129915 C:\Users\kores\PycharmProjects\NewSite\NewsSite\venv\Lib\site-packages\django\core\servers\basehttp.py
None
2025-08-11 21:04:53 ERROR Internal Server Error: / C:\Users\kores\PycharmProjects\NewSite\NewsSite\venv\Lib\site-packages\django\utils\log.py
None
Traceback (most recent call last):
  File "C:\Users\kores\PycharmProjects\NewSite\NewsSite\venv\Lib\site-packages\django\core\handlers\exception.py", line 55, in inner
    response = get_response(request)
  File "C:\Users\kores\PycharmProjects\NewSite\NewsSite\venv\Lib\site-packages\django\core\handlers\base.py", line 220, in _get_response
    response = response.render()
  File "C:\Users\kores\PycharmProjects\NewSite\NewsSite\venv\Lib\site-packages\django\template\response.py", line 114, in render
    self.content = self.rendered_content
                   ^^^^^^^^^^^^^^^^^^^^^
  File "C:\Users\kores\PycharmProjects\NewSite\NewsSite\venv\Lib\site-packages\django\template\response.py", line 92, in rendered_content
    return template.render(context, self._request)
           ~~~~~~~~~~~~~~~^^^^^^^^^^^^^^^^^^^^^^^^
  File "C:\Users\kores\PycharmProjects\NewSite\NewsSite\venv\Lib\site-packages\django\template\backends\django.py", line 107, in render
    return self.template.render(context)
           ~~~~~~~~~~~~~~~~~~~~^^^^^^^^^
  File "C:\Users\kores\PycharmProjects\NewSite\NewsSite\venv\Lib\site-packages\django\template\base.py", line 169, in render
    with context.bind_template(self):
         ~~~~~~~~~~~~~~~~~~~~~^^^^^^
  File "C:\Users\kores\AppData\Local\Programs\Python\Python313\Lib\contextlib.py", line 141, in __enter__
    return next(self.gen)
  File "C:\Users\kores\PycharmProjects\NewSite\NewsSite\venv\Lib\site-packages\django\template\context.py", line 259, in bind_template
    context = processor(self.request)
  File "C:\Users\kores\PycharmProjects\NewSite\NewsSite\news\context_processors.py", line 7, in timezone_context
    'timezones': pytz.all_timezones,
                 ^^^^
NameError: name 'pytz' is not defined
2025-08-11 21:04:53 ERROR "GET / HTTP/1.1" 500 105269 C:\Users\kores\PycharmProjects\NewSite\NewsSite\venv\Lib\site-packages\django\core\servers\basehttp.py
None
2025-08-11 21:04:54 ERROR Internal Server Error: / C:\Users\kores\PycharmProjects\NewSite\NewsSite\venv\Lib\site-packages\django\utils\log.py
None
Traceback (most recent call last):
  File "C:\Users\kores\PycharmProjects\NewSite\NewsSite\venv\Lib\site-packages\django\core\handlers\exception.py", line 55, in inner
    response = get_response(request)
  File "C:\Users\kores\PycharmProjects\NewSite\NewsSite\venv\Lib\site-packages\django\core\handlers\base.py", line 220, in _get_response
    response = response.render()
  File "C:\Users\kores\PycharmProjects\NewSite\NewsSite\venv\Lib\site-packages\django\template\response.py", line 114, in render
    self.content = self.rendered_content
                   ^^^^^^^^^^^^^^^^^^^^^
  File "C:\Users\kores\PycharmProjects\NewSite\NewsSite\venv\Lib\site-packages\django\template\response.py", line 92, in rendered_content
    return template.render(context, self._request)
           ~~~~~~~~~~~~~~~^^^^^^^^^^^^^^^^^^^^^^^^
  File "C:\Users\kores\PycharmProjects\NewSite\NewsSite\venv\Lib\site-packages\django\template\backends\django.py", line 107, in render
    return self.template.render(context)
           ~~~~~~~~~~~~~~~~~~~~^^^^^^^^^
  File "C:\Users\kores\PycharmProjects\NewSite\NewsSite\venv\Lib\site-packages\django\template\base.py", line 169, in render
    with context.bind_template(self):
         ~~~~~~~~~~~~~~~~~~~~~^^^^^^
  File "C:\Users\kores\AppData\Local\Programs\Python\Python313\Lib\contextlib.py", line 141, in __enter__
    return next(self.gen)
  File "C:\Users\kores\PycharmProjects\NewSite\NewsSite\venv\Lib\site-packages\django\template\context.py", line 259, in bind_template
    context = processor(self.request)
  File "C:\Users\kores\PycharmProjects\NewSite\NewsSite\news\context_processors.py", line 7, in timezone_context
    'timezones': pytz.all_timezones,
                 ^^^^
NameError: name 'pytz' is not defined
2025-08-11 21:04:54 ERROR "GET / HTTP/1.1" 500 105269 C:\Users\kores\PycharmProjects\NewSite\NewsSite\venv\Lib\site-packages\django\core\servers\basehttp.py
None
2025-08-11 21:06:32 ERROR Internal Server Error: / C:\Users\kores\PycharmProjects\NewSite\NewsSite\venv\Lib\site-packages\django\utils\log.py
None
Traceback (most recent call last):
  File "C:\Users\kores\PycharmProjects\NewSite\NewsSite\venv\Lib\site-packages\django\core\handlers\exception.py", line 55, in inner
    response = get_response(request)
  File "C:\Users\kores\PycharmProjects\NewSite\NewsSite\venv\Lib\site-packages\django\core\handlers\base.py", line 220, in _get_response
    response = response.render()
  File "C:\Users\kores\PycharmProjects\NewSite\NewsSite\venv\Lib\site-packages\django\template\response.py", line 114, in render
    self.content = self.rendered_content
                   ^^^^^^^^^^^^^^^^^^^^^
  File "C:\Users\kores\PycharmProjects\NewSite\NewsSite\venv\Lib\site-packages\django\template\response.py", line 92, in rendered_content
    return template.render(context, self._request)
           ~~~~~~~~~~~~~~~^^^^^^^^^^^^^^^^^^^^^^^^
  File "C:\Users\kores\PycharmProjects\NewSite\NewsSite\venv\Lib\site-packages\django\template\backends\django.py", line 107, in render
    return self.template.render(context)
           ~~~~~~~~~~~~~~~~~~~~^^^^^^^^^
  File "C:\Users\kores\PycharmProjects\NewSite\NewsSite\venv\Lib\site-packages\django\template\base.py", line 169, in render
    with context.bind_template(self):
         ~~~~~~~~~~~~~~~~~~~~~^^^^^^
  File "C:\Users\kores\AppData\Local\Programs\Python\Python313\Lib\contextlib.py", line 141, in __enter__
    return next(self.gen)
  File "C:\Users\kores\PycharmProjects\NewSite\NewsSite\venv\Lib\site-packages\django\template\context.py", line 259, in bind_template
    context = processor(self.request)
  File "C:\Users\kores\PycharmProjects\NewSite\NewsSite\news\context_processors.py", line 14, in theme_context
    'current_theme': request.session.get('theme', settings.DEFAULT_THEME),
                                                  ^^^^^^^^^^^^^^^^^^^^^^
  File "C:\Users\kores\PycharmProjects\NewSite\NewsSite\venv\Lib\site-packages\django\conf\__init__.py", line 83, in __getattr__
    val = getattr(_wrapped, name)
AttributeError: 'Settings' object has no attribute 'DEFAULT_THEME'. Did you mean: 'DEFAULT_CHARSET'?
2025-08-11 21:06:32 ERROR "GET / HTTP/1.1" 500 118956 C:\Users\kores\PycharmProjects\NewSite\NewsSite\venv\Lib\site-packages\django\core\servers\basehttp.py
None
